Workbook
Name Slicer_Diabetes_status: #N/A

Sheet CUSTOMER NAMES
A1: ORIGINAL DATA | E1: ORIGINAL DATA
A2: Customer ID | B2: name | E2: Customer ID | F2: Last name | G2: Title | H2: First name
A3: Id1 | B3: Hawks, Ms. Kelly | C3: a | E3: Id1 | F3: Hawks | G3: Ms | H3: Kelly
A4: Id2 | B4: Lehner, Mr. Matthew D | E4: Id2 | F4: Lehner | G4: Mr | H4: Matthew D
A5: Id3 | B5: Lu, Mr. Phil | E5: Id3 | F5: Lu | G5: Mr | H5: Phil
A6: Id4 | B6: Osborne, Ms. Kelsey | E6: Id4 | F6: Osborne | G6: Ms | H6: Kelsey
A7: Id5 | B7: Kadala, Ms. Kristyn | E7: Id5 | F7: Kadala | G7: Ms | H7: Kristyn
A8: Id6 | B8: Baker, Mr. Russell B. | E8: Id6 | F8: Baker | G8: Mr | H8: Russell B | BV8: `
A9: Id7 | B9: Macpherson, Mr. Scott | E9: Id7 | F9: Macpherson | G9: Mr | H9: Scott
A10: Id8 | B10: Hallman, Mr. Stephen | E10: Id8 | F10: Hallman | G10: Mr | H10: Stephen
A11: Id9 | B11: Moran, Mr. Patrick R. | E11: Id9 | F11: Moran | G11: Mr | H11: Patrick R
A12: Id10 | B12: Benner, Ms. Brooke N. | E12: Id10 | F12: Benner | G12: Ms | H12: Brooke N
A13: Id11 | B13: Fierro Vargas, Ms. Paola Andrea | E13: Id11 | F13: Fierro Vargas | G13: Ms | H13: Paola Andrea
A14: Id12 | B14: Franz, Mr. David | E14: Id12 | F14: Franz | G14: Mr | H14: David
A15: Id13 | B15: Foster, Mr. Wade | E15: Id13 | F15: Foster | G15: Mr | H15: Wade
A16: Id14 | B16: Tenorio, Mr. Franklin | E16: Id14 | F16: Tenorio | G16: Mr | H16: Franklin
A17: Id15 | B17: Rios, Ms. Leilani M. | E17: Id15 | F17: Rios | G17: Ms | H17: Leilani M
A18: Id16 | B18: Viau-Dupuis, Mr. Philippe | E18: Id16 | F18: Viau-Dupuis | G18: Mr | H18: Philippe
A19: Id17 | B19: Cronin, Ms. Jennifer A. | E19: Id17 | F19: Cronin | G19: Ms | H19: Jennifer A
A20: Id18 | B20: Noordstar, Ms. Christina M. | E20: Id18 | F20: Noordstar | G20: Ms | H20: Christina M
... A73: Id71 | B73: Turner, Mr. Jeff | E73: Id71 | F73: Turner | G73: Mr | H73: Jeff
A74: Id72 | B74: Rangel, Mr. Elenilton V. Sr. | E74: Id72 | F74: Rangel | G74: Mr | H74: Elenilton V | I74: Sr | L74: Sr
A75: Id73 | B75: Lacey, Ms. Maurya | E75: Id73 | F75: Lacey | G75: Ms | H75: Maurya
A76: Id74 | B76: Stiger, Ms. Samantha C | E76: Id74 | F76: Stiger | G76: Ms | H76: Samantha C
A77: Id75 | B77: Caldwell, Ms. Bethany A | E77: Id75 | F77: Caldwell | G77: Ms | H77: Bethany A
A78: Id76 | B78: Marmillod, Mr. Yves | E78: Id76 | F78: Marmillod | G78: Mr | H78: Yves
A79: Id77 | B79: Cloutier-Simons, Ms. Danielle | E79: Id77 | F79: Cloutier-Simons | G79: Ms | H79: Danielle
A80: Id78 | B80: Vegas, Ms. Julia | E80: Id78 | F80: Vegas | G80: Ms | H80: Julia
A81: Id79 | B81: Cochran, Mr. Joshua | E81: Id79 | F81: Cochran | G81: Mr | H81: Joshua
A82: Id80 | B82: Holtzapple, Ms. Jennifer | E82: Id80 | F82: Holtzapple | G82: Ms | H82: Jennifer
A83: Id81 | B83: Meyer, Ms. Gwen M. | E83: Id81 | F83: Meyer | G83: Ms | H83: Gwen M
A84: Id82 | B84: Brickley, Mr. Patrick | E84: Id82 | F84: Brickley | G84: Mr | H84: Patrick
A85: Id83 | B85: Magee, Ms. Kate | E85: Id83 | F85: Magee | G85: Ms | H85: Kate
A86: Id84 | B86: Thoma, Mr. Kevin | E86: Id84 | F86: Thoma | G86: Mr | H86: Kevin
... A189: Id187 | B189: Dublin, Mr. Andrew P | E189: Id187 | F189: Dublin | G189: Mr | H189: Andrew P
A190: Id188 | B190: Cleland, Mr. George M. V | E190: Id188 | F190: Cleland | G190: Mr | H190: George M | I190: V | L190: V
A191: Id189 | B191: Evans, Ms. Sarah | E191: Id189 | F191: Evans | G191: Ms | H191: Sarah
A192: Id190 | B192: Boyd, Ms. Lara | E192: Id190 | F192: Boyd | G192: Ms | H192: Lara
A193: Id191 | B193: Roulier, Mr. Sebastien | E193: Id191 | F193: Roulier | G193: Mr | H193: Sebastien
A194: Id192 | B194: Mullins, Mr. Padraig | E194: Id192 | F194: Mullins | G194: Mr | H194: Padraig
...

Sheet MEDICAL EXAMINATION
A1: ORIGINAL DATA | K1: REMOVED NULL VALUES AND COLUMN ADDED
A2: Customer ID | B2: BMI | C2: HBA1C | D2: Heart Issues | E2: Any Transplants | F2: Cancer history | G2: NumberOfMajorSurgeries | H2: smoker | K2: Customer ID | L2: BMI | M2: weight status | N2: HBA1C | O2: Diabetes status | P2: Heart Issues | Q2: Any Transplants | R2: Cancer history | S2: NumberOfMajorSurgeries | T2: smoker
A3: Id1 | B3: 47.41 | C3: 7.47 | D3: No | E3: No | F3: No | G3: No major surgery | H3: yes | K3: Id1 | L3: 47.41 | M3: =IF(L3<=18.5,"Underweight",IF(L3<=24.9,"Normal",IF(L3>=29.9,"OVERWEIGHT","OBESITY"))) -> OVERWEIGHT | N3: 7.47 | O3: =IF(N3<=5.7,"NORMAL",IF(N3<6.4,"PREDIABETES",IF(N3>=6.5,"DIABETES"))) -> DIABETES | P3: No | Q3: No | R3: No | S3: No major surgery | T3: yes
A4: Id2 | B4: 30.36 | C4: 5.77 | D4: No | E4: No | F4: No | G4: No major surgery | H4: yes | K4: Id2 | L4: 30.36 | M4: =IF(L4<=18.5,"Underweight",IF(L4<=24.9,"Normal",IF(L4>=29.9,"OVERWEIGHT","OBESITY"))) -> OVERWEIGHT | N4: 5.77 | O4: =IF(N4<=5.7,"NORMAL",IF(N4<6.4,"PREDIABETES",IF(N4>=6.5,"DIABETES"))) -> PREDIABETES | P4: No | Q4: No | R4: No | S4: No major surgery | T4: yes
A5: Id3 | B5: 34.485 | C5: 11.87 | D5: yes | E5: No | F5: No | G5: 2 | H5: yes | K5: Id3 | L5: 34.485 | M5: =IF(L5<=18.5,"Underweight",IF(L5<=24.9,"Normal",IF(L5>=29.9,"OVERWEIGHT","OBESITY"))) -> OVERWEIGHT | N5: 11.87 | O5: =IF(N5<=5.7,"NORMAL",IF(N5<6.4,"PREDIABETES",IF(N5>=6.5,"DIABETES"))) -> DIABETES | P5: yes | Q5: No | R5: No | S5: 2 | T5: yes
A6: Id4 | B6: 38.095 | C6: 6.05 | D6: No | E6: No | F6: No | G6: No major surgery | H6: yes | K6: Id4 | L6: 38.095 | M6: =IF(L6<=18.5,"Underweight",IF(L6<=24.9,"Normal",IF(L6>=29.9,"OVERWEIGHT","OBESITY"))) -> OVERWEIGHT | N6: 6.05 | O6: =IF(N6<=5.7,"NORMAL",IF(N6<6.4,"PREDIABETES",IF(N6>=6.5,"DIABETES"))) -> PREDIABETES | P6: No | Q6: No | R6: No | S6: No major surgery | T6: yes
A7: Id5 | B7: 35.53 | C7: 5.45 | D7: No | E7: No | F7: No | G7: No major surgery | H7: yes | K7: Id5 | L7: 35.53 | M7: =IF(L7<=18.5,"Underweight",IF(L7<=24.9,"Normal",IF(L7>=29.9,"OVERWEIGHT","OBESITY"))) -> OVERWEIGHT | N7: 5.45 | O7: =IF(N7<=5.7,"NORMAL",IF(N7<6.4,"PREDIABETES",IF(N7>=6.5,"DIABETES"))) -> NORMAL | P7: No | Q7: No | R7: No | S7: No major surgery | T7: yes
A8: Id6 | B8: 32.8 | C8: 6.59 | D8: No | E8: No | F8: No | G8: No major surgery | H8: yes | K8: Id6 | L8: 32.8 | M8: =IF(L8<=18.5,"Underweight",IF(L8<=24.9,"Normal",IF(L8>=29.9,"OVERWEIGHT","OBESITY"))) -> OVERWEIGHT | N8: 6.59 | O8: =IF(N8<=5.7,"NORMAL",IF(N8<6.4,"PREDIABETES",IF(N8>=6.5,"DIABETES"))) -> DIABETES | P8: No | Q8: No | R8: No | S8: No major surgery | T8: yes
A9: Id7 | B9: 36.4 | C9: 6.07 | D9: No | E9: No | F9: No | G9: No major surgery | H9: yes | K9: Id7 | L9: 36.4 | M9: =IF(L9<=18.5,"Underweight",IF(L9<=24.9,"Normal",IF(L9>=29.9,"OVERWEIGHT","OBESITY"))) -> OVERWEIGHT | N9: 6.07 | O9: =IF(N9<=5.7,"NORMAL",IF(N9<6.4,"PREDIABETES",IF(N9>=6.5,"DIABETES"))) -> PREDIABETES | P9: No | Q9: No | R9: No | S9: No major surgery | T9: yes
A10: Id8 | B10: 36.96 | C10: 7.93 | D10: No | E10: No | F10: No | G10: 3 | H10: yes | K10: Id8 | L10: 36.96 | M10: =IF(L10<=18.5,"Underweight",IF(L10<=24.9,"Normal",IF(L10>=29.9,"OVERWEIGHT","OBESITY"))) -> OVERWEIGHT | N10: 7.93 | O10: =IF(N10<=5.7,"NORMAL",IF(N10<6.4,"PREDIABETES",IF(N10>=6.5,"DIABETES"))) -> DIABETES | P10: No | Q10: No | R10: No | S10: 3 | T10: yes
A11: Id9 | B11: 41.14 | C11: 9.58 | D11: yes | E11: No | F11: Yes | G11: 1 | H11: yes | K11: Id9 | L11: 41.14 | M11: =IF(L11<=18.5,"Underweight",IF(L11<=24.9,"Normal",IF(L11>=29.9,"OVERWEIGHT","OBESITY"))) -> OVERWEIGHT | N11: 9.58 | O11: =IF(N11<=5.7,"NORMAL",IF(N11<6.4,"PREDIABETES",IF(N11>=6.5,"DIABETES"))) -> DIABETES | P11: yes | Q11: No | R11: Yes | S11: 1 | T11: yes
A12: Id10 | B12: 38.06 | C12: 10.79 | D12: No | E12: No | F12: No | G12: No major surgery | H12: yes | K12: Id10 | L12: 38.06 | M12: =IF(L12<=18.5,"Underweight",IF(L12<=24.9,"Normal",IF(L12>=29.9,"OVERWEIGHT","OBESITY"))) -> OVERWEIGHT | N12: 10.79 | O12: =IF(N12<=5.7,"NORMAL",IF(N12<6.4,"PREDIABETES",IF(N12>=6.5,"DIABETES"))) -> DIABETES | P12: No | Q12: No | R12: No | S12: No major surgery | T12: yes
A13: Id11 | B13: 37.7 | C13: 5.96 | D13: yes | E13: No | F13: No | G13: 2 | H13: yes | K13: Id11 | L13: 37.7 | M13: =IF(L13<=18.5,"Underweight",IF(L13<=24.9,"Normal",IF(L13>=29.9,"OVERWEIGHT","OBESITY"))) -> OVERWEIGHT | N13: 5.96 | O13: =IF(N13<=5.7,"NORMAL",IF(N13<6.4,"PREDIABETES",IF(N13>=6.5,"DIABETES"))) -> PREDIABETES | P13: yes | Q13: No | R13: No | S13: 2 | T13: yes
A14: Id12 | B14: 42.13 | C14: 11.9 | D14: No | E14: No | F14: No | G14: No major surgery | H14: yes | K14: Id12 | L14: 42.13 | M14: =IF(L14<=18.5,"Underweight",IF(L14<=24.9,"Normal",IF(L14>=29.9,"OVERWEIGHT","OBESITY"))) -> OVERWEIGHT | N14: 11.9 | O14: =IF(N14<=5.7,"NORMAL",IF(N14<6.4,"PREDIABETES",IF(N14>=6.5,"DIABETES"))) -> DIABETES | P14: No | Q14: No | R14: No | S14: No major surgery | T14: yes
A15: Id13 | B15: 40.92 | C15: 8.41 | D15: No | E15: No | F15: No | G15: No major surgery | H15: yes | K15: Id13 | L15: 40.92 | M15: =IF(L15<=18.5,"Underweight",IF(L15<=24.9,"Normal",IF(L15>=29.9,"OVERWEIGHT","OBESITY"))) -> OVERWEIGHT | N15: 8.41 | O15: =IF(N15<=5.7,"NORMAL",IF(N15<6.4,"PREDIABETES",IF(N15>=6.5,"DIABETES"))) -> DIABETES | P15: No | Q15: No | R15: No | S15: No major surgery | T15: yes
A16: Id14 | B16: 40.565 | C16: 7.02 | D16: No | E16: No | F16: No | G16: No major surgery | H16: yes | K16: Id14 | L16: 40.565 | M16: =IF(L16<=18.5,"Underweight",IF(L16<=24.9,"Normal",IF(L16>=29.9,"OVERWEIGHT","OBESITY"))) -> OVERWEIGHT | N16: 7.02 | O16: =IF(N16<=5.7,"NORMAL",IF(N16<6.4,"PREDIABETES",IF(N16>=6.5,"DIABETES"))) -> DIABETES | P16: No | Q16: No | R16: No | S16: No major surgery | T16: yes
A17: Id15 | B17: 36.385 | C17: 7.59 | D17: yes | E17: No | F17: No | G17: 2 | H17: yes | K17: Id15 | L17: 36.385 | M17: =IF(L17<=18.5,"Underweight",IF(L17<=24.9,"Normal",IF(L17>=29.9,"OVERWEIGHT","OBESITY"))) -> OVERWEIGHT | N17: 7.59 | O17: =IF(N17<=5.7,"NORMAL",IF(N17<6.4,"PREDIABETES",IF(N17>=6.5,"DIABETES"))) -> DIABETES | P17: yes | Q17: No | R17: No | S17: 2 | T17: yes
A18: Id16 | B18: 39.9 | C18: 11.32 | D18: No | E18: No | F18: No | G18: No major surgery | H18: yes | K18: Id16 | L18: 39.9 | M18: =IF(L18<=18.5,"Underweight",IF(L18<=24.9,"Normal",IF(L18>=29.9,"OVERWEIGHT","OBESITY"))) -> OVERWEIGHT | N18: 11.32 | O18: =IF(N18<=5.7,"NORMAL",IF(N18<6.4,"PREDIABETES",IF(N18>=6.5,"DIABETES"))) -> DIABETES | P18: No | Q18: No | R18: No | S18: No major surgery | T18: yes
A19: Id17 | B19: 33.8 | C19: 7.67 | D19: No | E19: No | F19: No | G19: 3 | H19: yes | K19: Id17 | L19: 33.8 | M19: =IF(L19<=18.5,"Underweight",IF(L19<=24.9,"Normal",IF(L19>=29.9,"OVERWEIGHT","OBESITY"))) -> OVERWEIGHT | N19: 7.67 | O19: =IF(N19<=5.7,"NORMAL",IF(N19<6.4,"PREDIABETES",IF(N19>=6.5,"DIABETES"))) -> DIABETES | P19: No | Q19: No | R19: No | S19: 3 | T19: yes
A20: Id18 | B20: 36.765 | C20: 7.29 | D20: yes | E20: No | F20: Yes | G20: 1 | H20: yes | K20: Id18 | L20: 36.765 | M20: =IF(L20<=18.5,"Underweight",IF(L20<=24.9,"Normal",IF(L20>=29.9,"OVERWEIGHT","OBESITY"))) -> OVERWEIGHT | N20: 7.29 | O20: =IF(N20<=5.7,"NORMAL",IF(N20<6.4,"PREDIABETES",IF(N20>=6.5,"DIABETES"))) -> DIABETES | P20: yes | Q20: No | R20: Yes | S20: 1 | T20: yes
A21: Id19 | B21: 36.955 | C21: 4.72 | D21: yes | E21: No | F21: No | G21: 1 | H21: yes | K21: Id19 | L21: 36.955 | M21: =IF(L21<=18.5,"Underweight",IF(L21<=24.9,"Normal",IF(L21>=29.9,"OVERWEIGHT","OBESITY"))) -> OVERWEIGHT | N21: 4.72 | O21: =IF(N21<=5.7,"NORMAL",IF(N21<6.4,"PREDIABETES",IF(N21>=6.5,"DIABETES"))) -> NORMAL | P21: yes | Q21: No | R21: No | S21: 1 | T21: yes
A22: Id20 | B22: 42.9 | C22: 11.41 | D22: No | E22: No | F22: No | G22: No major surgery | H22: yes | K22: Id20 | L22: 42.9 | M22: =IF(L22<=18.5,"Underweight",IF(L22<=24.9,"Normal",IF(L22>=29.9,"OVERWEIGHT","OBESITY"))) -> OVERWEIGHT | N22: 11.41 | O22: =IF(N22<=5.7,"NORMAL",IF(N22<6.4,"PREDIABETES",IF(N22>=6.5,"DIABETES"))) -> DIABETES | P22: No | Q22: No | R22: No | S22: No major surgery | T22: yes
A23: Id21 | B23: 36.3 | C23: 11.5 | D23: yes | E23: No | F23: No | G23: 2 | H23: yes | K23: Id21 | L23: 36.3 | M23: =IF(L23<=18.5,"Underweight",IF(L23<=24.9,"Normal",IF(L23>=29.9,"OVERWEIGHT","OBESITY"))) -> OVERWEIGHT | N23: 11.5 | O23: =IF(N23<=5.7,"NORMAL",IF(N23<6.4,"PREDIABETES",IF(N23>=6.5,"DIABETES"))) -> DIABETES | P23: yes | Q23: No | R23: No | S23: 2 | T23: yes
A24: Id22 | B24: 32.2 | C24: 6.22 | D24: yes | E24: No | F24: No | G24: 2 | H24: yes | K24: Id22 | L24: 32.2 | M24: =IF(L24<=18.5,"Underweight",IF(L24<=24.9,"Normal",IF(L24>=29.9,"OVERWEIGHT","OBESITY"))) -> OVERWEIGHT | N24: 6.22 | O24: =IF(N24<=5.7,"NORMAL",IF(N24<6.4,"PREDIABETES",IF(N24>=6.5,"DIABETES"))) -> PREDIABETES | P24: yes | Q24: No | R24: No | S24: 2 | T24: yes
A25: Id23 | B25: 31.3 | C25: 11.38 | D25: No | E25: No | F25: No | G25: 3 | H25: yes | K25: Id23 | L25: 31.3 | M25: =IF(L25<=18.5,"Underweight",IF(L25<=24.9,"Normal",IF(L25>=29.9,"OVERWEIGHT","OBESITY"))) -> OVERWEIGHT | N25: 11.38 | O25: =IF(N25<=5.7,"NORMAL",IF(N25<6.4,"PREDIABETES",IF(N25>=6.5,"DIABETES"))) -> DIABETES | P25: No | Q25: No | R25: No | S25: 3 | T25: yes
A26: Id24 | B26: 41.8 | C26: 7.89 | D26: yes | E26: No | F26: No | G26: 2 | H26: yes | K26: Id24 | L26: 41.8 | M26: =IF(L26<=18.5,"Underweight",IF(L26<=24.9,"Normal",IF(L26>=29.9,"OVERWEIGHT","OBESITY"))) -> OVERWEIGHT | N26: 7.89 | O26: =IF(N26<=5.7,"NORMAL",IF(N26<6.4,"PREDIABETES",IF(N26>=6.5,"DIABETES"))) -> DIABETES | P26: yes | Q26: No | R26: No | S26: 2 | T26: yes
A27: Id25 | B27: 35.09 | C27: 4.38 | D27: yes | E27: No | F27: No | G27: 2 | H27: yes | K27: Id25 | L27: 35.09 | M27: =IF(L27<=18.5,"Underweight",IF(L27<=24.9,"Normal",IF(L27>=29.9,"OVERWEIGHT","OBESITY"))) -> OVERWEIGHT | N27: 4.38 | O27: =IF(N27<=5.7,"NORMAL",IF(N27<6.4,"PREDIABETES",IF(N27>=6.5,"DIABETES"))) -> NORMAL | P27: yes | Q27: No | R27: No | S27: 2 | T27: yes
A28: Id26 | B28: 33.88 | C28: 7.01 | D28: No | E28: No | F28: No | G28: 3 | H28: yes | K28: Id26 | L28: 33.88 | M28: =IF(L28<=18.5,"Underweight",IF(L28<=24.9,"Normal",IF(L28>=29.9,"OVERWEIGHT","OBESITY"))) -> OVERWEIGHT | N28: 7.01 | O28: =IF(N28<=5.7,"NORMAL",IF(N28<6.4,"PREDIABETES",IF(N28>=6.5,"DIABETES"))) -> DIABETES | P28: No | Q28: No | R28: No | S28: 3 | T28: yes
A29: Id27 | B29: 30.875 | C29: 11.88 | D29: No | E29: No | F29: No | G29: No major surgery | H29: yes | K29: Id27 | L29: 30.875 | M29: =IF(L29<=18.5,"Underweight",IF(L29<=24.9,"Normal",IF(L29>=29.9,"OVERWEIGHT","OBESITY"))) -> OVERWEIGHT | N29: 11.88 | O29: =IF(N29<=5.7,"NORMAL",IF(N29<6.4,"PREDIABETES",IF(N29>=6.5,"DIABETES"))) -> DIABETES | P29: No | Q29: No | R29: No | S29: No major surgery | T29: yes
A30: Id28 | B30: 36.86 | C30: 5.19 | D30: yes | E30: No | F30: Yes | G30: 1 | H30: yes | K30: Id28 | L30: 36.86 | M30: =IF(L30<=18.5,"Underweight",IF(L30<=24.9,"Normal",IF(L30>=29.9,"OVERWEIGHT","OBESITY"))) -> OVERWEIGHT | N30: 5.19 | O30: =IF(N30<=5.7,"NORMAL",IF(N30<6.4,"PREDIABETES",IF(N30>=6.5,"DIABETES"))) -> NORMAL | P30: yes | Q30: No | R30: Yes | S30: 1 | T30: yes
A31: Id29 | B31: 35.86 | C31: 6.74 | D31: yes | E31: No | F31: No | G31: 2 | H31: yes | K31: Id29 | L31: 35.86 | M31: =IF(L31<=18.5,"Underweight",IF(L31<=24.9,"Normal",IF(L31>=29.9,"OVERWEIGHT","OBESITY"))) -> OVERWEIGHT | N31: 6.74 | O31: =IF(N31<=5.7,"NORMAL",IF(N31<6.4,"PREDIABETES",IF(N31>=6.5,"DIABETES"))) -> DIABETES | P31: yes | Q31: No | R31: No | S31: 2 | T31: yes
A32: Id30 | B32: 37.05 | C32: 8.44 | D32: No | E32: No | F32: No | G32: No major surgery | H32: yes | K32: Id30 | L32: 37.05 | M32: =IF(L32<=18.5,"Underweight",IF(L32<=24.9,"Normal",IF(L32>=29.9,"OVERWEIGHT","OBESITY"))) -> OVERWEIGHT | N32: 8.44 | O32: =IF(N32<=5.7,"NORMAL",IF(N32<6.4,"PREDIABETES",IF(N32>=6.5,"DIABETES"))) -> DIABETES | P32: No | Q32: No | R32: No | S32: No major surgery | T32: yes
A33: Id31 | B33: 43.89 | C33: 8.71 | D33: No | E33: No | F33: No | G33: No major surgery | H33: yes | K33: Id31 | L33: 43.89 | M33: =IF(L33<=18.5,"Underweight",IF(L33<=24.9,"Normal",IF(L33>=29.9,"OVERWEIGHT","OBESITY"))) -> OVERWEIGHT | N33: 8.71 | O33: =IF(N33<=5.7,"NORMAL",IF(N33<6.4,"PREDIABETES",IF(N33>=6.5,"DIABETES"))) -> DIABETES | P33: No | Q33: No | R33: No | S33: No major surgery | T33: yes
A34: Id32 | B34: 42.35 | C34: 5.08 | D34: yes | E34: No | F34: No | G34: No major surgery | H34: yes | K34: Id32 | L34: 42.35 | M34: =IF(L34<=18.5,"Underweight",IF(L34<=24.9,"Normal",IF(L34>=29.9,"OVERWEIGHT","OBESITY"))) -> OVERWEIGHT | N34: 5.08 | O34: =IF(N34<=5.7,"NORMAL",IF(N34<6.4,"PREDIABETES",IF(N34>=6.5,"DIABETES"))) -> NORMAL | P34: yes | Q34: No | R34: No | S34: No major surgery | T34: yes
A35: Id33 | B35: 31.35 | C35: 6.86 | D35: No | E35: No | F35: No | G35: No major surgery | H35: yes | K35: Id33 | L35: 31.35 | M35: =IF(L35<=18.5,"Underweight",IF(L35<=24.9,"Normal",IF(L35>=29.9,"OVERWEIGHT","OBESITY"))) -> OVERWEIGHT | N35: 6.86 | O35: =IF(N35<=5.7,"NORMAL",IF(N35<6.4,"PREDIABETES",IF(N35>=6.5,"DIABETES"))) -> DIABETES | P35: No | Q35: No | R35: No | S35: No major surgery | T35: yes
A36: Id34 | B36: 47.6 | C36: 5.95 | D36: yes | E36: No | F36: No | G36: No major surgery | H36: yes | K36: Id34 | L36: 47.6 | M36: =IF(L36<=18.5,"Underweight",IF(L36<=24.9,"Normal",IF(L36>=29.9,"OVERWEIGHT","OBESITY"))) -> OVERWEIGHT | N36: 5.95 | O36: =IF(N36<=5.7,"NORMAL",IF(N36<6.4,"PREDIABETES",IF(N36>=6.5,"DIABETES"))) -> PREDIABETES | P36: yes | Q36: No | R36: No | S36: No major surgery | T36: yes
A37: Id35 | B37: 46.2 | C37: 6.09 | D37: No | E37: No | F37: Yes | G37: 1 | H37: yes | K37: Id35 | L37: 46.2 | M37: =IF(L37<=18.5,"Underweight",IF(L37<=24.9,"Normal",IF(L37>=29.9,"OVERWEIGHT","OBESITY"))) -> OVERWEIGHT | N37: 6.09 | O37: =IF(N37<=5.7,"NORMAL",IF(N37<6.4,"PREDIABETES",IF(N37>=6.5,"DIABETES"))) -> PREDIABETES | P37: No | Q37: No | R37: Yes | S37: 1 | T37: yes
A38: Id36 | B38: 32.015 | C38: 11.75 | D38: No | E38: No | F38: No | G38: No major surgery | H38: yes | K38: Id36 | L38: 32.015 | M38: =IF(L38<=18.5,"Underweight",IF(L38<=24.9,"Normal",IF(L38>=29.9,"OVERWEIGHT","OBESITY"))) -> OVERWEIGHT | N38: 11.75 | O38: =IF(N38<=5.7,"NORMAL",IF(N38<6.4,"PREDIABETES",IF(N38>=6.5,"DIABETES"))) -> DIABETES | P38: No | Q38: No | R38: No | S38: No major surgery | T38: yes
A39: Id37 | B39: 40.565 | C39: 7.37 | D39: No | E39: No | F39: No | G39: No major surgery | H39: yes | K39: Id37 | L39: 40.565 | M39: =IF(L39<=18.5,"Underweight",IF(L39<=24.9,"Normal",IF(L39>=29.9,"OVERWEIGHT","OBESITY"))) -> OVERWEIGHT | N39: 7.37 | O39: =IF(N39<=5.7,"NORMAL",IF(N39<6.4,"PREDIABETES",IF(N39>=6.5,"DIABETES"))) -> DIABETES | P39: No | Q39: No | R39: No | S39: No major surgery | T39: yes
A40: Id38 | B40: 32.45 | C40: 11.91 | D40: No | E40: No | F40: No | G40: No major surgery | H40: yes | K40: Id38 | L40: 32.45 | M40: =IF(L40<=18.5,"Underweight",IF(L40<=24.9,"Normal",IF(L40>=29.9,"OVERWEIGHT","OBESITY"))) -> OVERWEIGHT | N40: 11.91 | O40: =IF(N40<=5.7,"NORMAL",IF(N40<6.4,"PREDIABETES",IF(N40>=6.5,"DIABETES"))) -> DIABETES | P40: No | Q40: No | R40: No | S40: No major surgery | T40: yes
...

Sheet HOSPITALIZATION DETAILS
A1: ORIGINAL DATA | L1: FINDING NULL AND REPLACED | X1: Merging and inserting a new column
A2: Customer ID | B2: year | C2: month | D2: date | E2: children | F2: charges | G2: Hospital tier | H2: City tier | I2: State ID | L2: Customer ID | M2: year | N2: month | O2: date | P2: children | Q2: charges | R2: Hospital tier | S2: City tier | T2: State ID | X2: Customer ID | Y2: Merged column | Z2: children | AA2: charges | AB2: Hospital tier | AC2: City tier | AD2: State ID | AE2: Date of birth | AF2: date of collection of dataset | AG2: Age
A3: Id2335 | B3: 1992 | C3: Jul | D3: 9 | E3: 0 | F3: 563.84 | G3: tier - 2 | H3: tier - 3 | I3: R1013 | L3: Id1 | M3: 1968 | N3: Oct | O3: 12 | P3: 0 | Q3: 63770.43 | R3: tier - 1 | S3: tier - 3 | T3: R1013 | X3: Id1 | Y3: =_xlfn.CONCAT(O3,"- ",N3,"- ",M3) -> 12- Oct- 1968 | Z3: 0 | AA3: 63770.43 | AB3: tier - 1 | AC3: tier - 3 | AD3: R1013 | AE3: =TEXT(Y3,"dd/mm/yyyy") -> 12/10/1968 | AF3: 45085 | AG3: =DATEDIF(AE3,AF3,"y") -> 54
A4: Id2334 | B4: 1992 | C4: Nov | D4: 30 | E4: 0 | F4: 570.62 | G4: tier - 2 | H4: tier - 1 | I4: R1013 | L4: Id10 | M4: 1978 | N4: Dec | O4: 29 | P4: 0 | Q4: 48885.14 | R4: tier - 1 | S4: tier - 2 | T4: R1013 | X4: Id2 | Y4: =_xlfn.CONCAT(O4,"- ",N4,"- ",M4) -> 29- Dec- 1978 | Z4: 0 | AA4: 48885.14 | AB4: tier - 1 | AC4: tier - 2 | AD4: R1013 | AE4: =TEXT(Y4,"dd/mm/yyyy") -> 29/12/1978 | AF4: 45085 | AG4: =DATEDIF(AE4,AF4,"y") -> 44
A5: Id2333 | B5: 1993 | C5: Jun | D5: 30 | E5: 0 | F5: 600 | G5: tier - 2 | H5: tier - 1 | I5: R1013 | L5: Id100 | M5: 1977 | N5: Jun | O5: 27 | P5: 2 | Q5: 40284.38 | R5: tier - 1 | S5: tier - 3 | T5: R1012 | X5: Id3 | Y5: =_xlfn.CONCAT(O5,"- ",N5,"- ",M5) -> 27- Jun- 1977 | Z5: 2 | AA5: 40284.38 | AB5: tier - 1 | AC5: tier - 3 | AD5: R1012 | AE5: =TEXT(Y5,"dd/mm/yyyy") -> 27/06/1977 | AF5: 45085 | AG5: =DATEDIF(AE5,AF5,"y") -> 45
A6: Id2332 | B6: 1992 | C6: Sep | D6: 13 | E6: 0 | F6: 604.54 | G6: tier - 3 | H6: tier - 3 | I6: R1013 | L6: Id1000 | M6: 1989 | N6: Dec | O6: 17 | P6: 3 | Q6: 11250.43 | R6: tier - 3 | S6: tier - 2 | T6: R1026 | X6: Id4 | Y6: =_xlfn.CONCAT(O6,"- ",N6,"- ",M6) -> 17- Dec- 1989 | Z6: 3 | AA6: 11250.43 | AB6: tier - 3 | AC6: tier - 2 | AD6: R1026 | AE6: =TEXT(Y6,"dd/mm/yyyy") -> 17/12/1989 | AF6: 45085 | AG6: =DATEDIF(AE6,AF6,"y") -> 33
A7: Id2331 | B7: 1998 | C7: Jul | D7: 27 | E7: 0 | F7: 637.26 | G7: tier - 3 | H7: tier - 3 | I7: R1013 | L7: Id1001 | M7: 1969 | N7: Dec | O7: 30 | P7: 2 | Q7: 11244.38 | R7: tier - 3 | S7: tier - 1 | T7: R1016 | X7: Id5 | Y7: =_xlfn.CONCAT(O7,"- ",N7,"- ",M7) -> 30- Dec- 1969 | Z7: 2 | AA7: 11244.38 | AB7: tier - 3 | AC7: tier - 1 | AD7: R1016 | AE7: =TEXT(Y7,"dd/mm/yyyy") -> 30/12/1969 | AF7: 45085 | AG7: =DATEDIF(AE7,AF7,"y") -> 53
A8: Id2330 | B8: 2001 | C8: Nov | D8: 20 | E8: 0 | F8: 646.14 | G8: tier - 3 | H8: tier - 3 | I8: R1012 | L8: Id1002 | M8: 1976 | N8: Jun | O8: 28 | P8: 2 | Q8: 11217.35 | R8: tier - 3 | S8: tier - 2 | T8: R1025 | X8: Id6 | Y8: =_xlfn.CONCAT(O8,"- ",N8,"- ",M8) -> 28- Jun- 1976 | Z8: 2 | AA8: 11217.35 | AB8: tier - 3 | AC8: tier - 2 | AD8: R1025 | AE8: =TEXT(Y8,"dd/mm/yyyy") -> 28/06/1976 | AF8: 45085 | AG8: =DATEDIF(AE8,AF8,"y") -> 46
A9: Id2329 | B9: 1993 | C9: Jun | D9: 1 | E9: 0 | F9: 650 | G9: tier - 3 | H9: tier - 3 | I9: R1013 | L9: Id1003 | M9: 1970 | N9: Jun | O9: 14 | P9: 2 | Q9: 11187.66 | R9: tier - 3 | S9: tier - 2 | T9: R1012 | X9: Id7 | Y9: =_xlfn.CONCAT(O9,"- ",N9,"- ",M9) -> 14- Jun- 1970 | Z9: 2 | AA9: 11187.66 | AB9: tier - 3 | AC9: tier - 2 | AD9: R1012 | AE9: =TEXT(Y9,"dd/mm/yyyy") -> 14/06/1970 | AF9: 45085 | AG9: =DATEDIF(AE9,AF9,"y") -> 52
A10: Id2328 | B10: 1995 | C10: Jul | D10: 4 | E10: 0 | F10: 650 | G10: tier - 3 | H10: tier - 3 | I10: R1013 | L10: Id1004 | M10: 1972 | N10: Sep | O10: 3 | P10: 0 | Q10: 11186.2 | R10: tier - 3 | S10: tier - 2 | T10: R1021 | X10: Id8 | Y10: =_xlfn.CONCAT(O10,"- ",N10,"- ",M10) -> 3- Sep- 1972 | Z10: 0 | AA10: 11186.2 | AB10: tier - 3 | AC10: tier - 2 | AD10: R1021 | AE10: =TEXT(Y10,"dd/mm/yyyy") -> 03/09/1972 | AF10: 45085 | AG10: =DATEDIF(AE10,AF10,"y") -> 50
A11: Id2327 | B11: 2002 | C11: Nov | D11: 29 | E11: 0 | F11: 668 | G11: tier - 3 | H11: tier - 2 | I11: R1012 | L11: Id1005 | M11: 1966 | N11: Aug | O11: 6 | P11: 0 | Q11: 11165.42 | R11: tier - 3 | S11: tier - 1 | T11: R1016 | X11: Id9 | Y11: =_xlfn.CONCAT(O11,"- ",N11,"- ",M11) -> 6- Aug- 1966 | Z11: 0 | AA11: 11165.42 | AB11: tier - 3 | AC11: tier - 1 | AD11: R1016 | AE11: =TEXT(Y11,"dd/mm/yyyy") -> 06/08/1966 | AF11: 45085 | AG11: =DATEDIF(AE11,AF11,"y") -> 56
A12: Id2326 | B12: 1997 | C12: Nov | D12: 9 | E12: 0 | F12: 670 | G12: tier - 3 | H12: tier - 3 | I12: R1013 | L12: Id1006 | M12: 1969 | N12: Jun | O12: 25 | P12: 2 | Q12: 11163.57 | R12: tier - 3 | S12: tier - 2 | T12: R1011 | X12: Id10 | Y12: =_xlfn.CONCAT(O12,"- ",N12,"- ",M12) -> 25- Jun- 1969 | Z12: 2 | AA12: 11163.57 | AB12: tier - 3 | AC12: tier - 2 | AD12: R1011 | AE12: =TEXT(Y12,"dd/mm/yyyy") -> 25/06/1969 | AF12: 45085 | AG12: =DATEDIF(AE12,AF12,"y") -> 53
A13: Id2325 | B13: 2001 | C13: Sep | D13: 12 | E13: 0 | F13: 687.54 | G13: tier - 3 | H13: tier - 2 | I13: R1013 | L13: Id1007 | M13: 1969 | N13: Nov | O13: 30 | P13: 2 | Q13: 11150.78 | R13: tier - 3 | S13: tier - 2 | T13: R1011 | X13: Id11 | Y13: =_xlfn.CONCAT(O13,"- ",N13,"- ",M13) -> 30- Nov- 1969 | Z13: 2 | AA13: 11150.78 | AB13: tier - 3 | AC13: tier - 2 | AD13: R1011 | AE13: =TEXT(Y13,"dd/mm/yyyy") -> 30/11/1969 | AF13: 45085 | AG13: =DATEDIF(AE13,AF13,"y") -> 53
A14: Id2324 | B14: 1999 | C14: Dec | D14: 26 | E14: 0 | F14: 700 | G14: ? | H14: tier - 3 | I14: R1013 | L14: Id1008 | M14: 1980 | N14: Aug | O14: 20 | P14: 2 | Q14: 11103.33 | R14: tier - 3 | S14: tier - 1 | T14: R1021 | X14: Id12 | Y14: =_xlfn.CONCAT(O14,"- ",N14,"- ",M14) -> 20- Aug- 1980 | Z14: 2 | AA14: 11103.33 | AB14: tier - 3 | AC14: tier - 1 | AD14: R1021 | AE14: =TEXT(Y14,"dd/mm/yyyy") -> 20/08/1980 | AF14: 45085 | AG14: =DATEDIF(AE14,AF14,"y") -> 42
... A1051: Id1290 | B1051: 1977 | C1051: Jul | D1051: 26 | E1051: 2 | F1051: 8527.53 | G1051: tier - 2 | H1051: tier - 2 | I1051: R1013 | L1051: Id1942 | M1051: 2003 | N1051: Jul | O1051: 10 | P1051: 0 | Q1051: 3688.35 | R1051: tier - 2 | S1051: tier - 2 | T1051: R1021 | X1051: Id1049 | Y1051: =_xlfn.CONCAT(O1051,"- ",N1051,"- ",M1051) -> 10- Jul- 2003 | Z1051: 0 | AA1051: 3688.35 | AB1051: tier - 2 | AC1051: tier - 2 | AD1051: R1021 | AE1051: =TEXT(Y1051,"dd/mm/yyyy") -> 10/07/2003 | AF1051: 45085 | AG1051: =DATEDIF(AE1051,AF1051,"y") -> 19
A1052: Id1289 | B1052: ? | C1052: Jul | D1052: 24 | E1052: 0 | F1052: 8534.67 | G1052: tier - 2 | H1052: tier - 3 | I1052: R1024 | L1052: Id1943 | M1052: 1984 | N1052: Jul | O1052: 6 | P1052: 3 | Q1052: 3678.86 | R1052: tier - 2 | S1052: tier - 3 | T1052: R1013 | X1052: Id1050 | Y1052: =_xlfn.CONCAT(O1052,"- ",N1052,"- ",M1052) -> 6- Jul- 1984 | Z1052: 3 | AA1052: 3678.86 | AB1052: tier - 2 | AC1052: tier - 3 | AD1052: R1013 | AE1052: =TEXT(Y1052,"dd/mm/yyyy") -> 06/07/1984 | AF1052: 45085 | AG1052: =DATEDIF(AE1052,AF1052,"y") -> 38
A1053: Id1288 | B1053: 1981 | C1053: Dec | D1053: 27 | E1053: 3 | F1053: 8538.29 | G1053: tier - 2 | H1053: tier - 3 | I1053: R1024 | L1053: Id1944 | M1053: 1992 | N1053: Sep | O1053: 14 | P1053: 1 | Q1053: 3659.35 | R1053: tier - 3 | S1053: tier - 1 | T1053: R1011 | X1053: Id1051 | Y1053: =_xlfn.CONCAT(O1053,"- ",N1053,"- ",M1053) -> 14- Sep- 1992 | Z1053: 1 | AA1053: 3659.35 | AB1053: tier - 3 | AC1053: tier - 1 | AD1053: R1011 | AE1053: =TEXT(Y1053,"dd/mm/yyyy") -> 14/09/1992 | AF1053: 45085 | AG1053: =DATEDIF(AE1053,AF1053,"y") -> 30
A1054: Id1287 | B1054: 1975 | C1054: Nov | D1054: 6 | E1054: 1 | F1054: 8539.67 | G1054: tier - 2 | H1054: tier - 3 | I1054: R1011 | L1054: Id1945 | M1054: 1990 | N1054: Nov | O1054: 8 | P1054: 3 | Q1054: 3653.29 | R1054: tier - 2 | S1054: tier - 3 | T1054: R1011 | X1054: Id1052 | Y1054: =_xlfn.CONCAT(O1054,"- ",N1054,"- ",M1054) -> 8- Nov- 1990 | Z1054: 3 | AA1054: 3653.29 | AB1054: tier - 2 | AC1054: tier - 3 | AD1054: R1011 | AE1054: =TEXT(Y1054,"dd/mm/yyyy") -> 08/11/1990 | AF1054: 45085 | AG1054: =DATEDIF(AE1054,AF1054,"y") -> 32
A1055: Id1286 | B1055: ? | C1055: Dec | D1055: 12 | E1055: 1 | F1055: 8547.69 | G1055: tier - 2 | H1055: tier - 1 | I1055: R1013 | L1055: Id1946 | M1055: 1992 | N1055: Nov | O1055: 17 | P1055: 0 | Q1055: 3645.09 | R1055: tier - 1 | S1055: tier - 2 | T1055: R1014 | X1055: Id1053 | Y1055: =_xlfn.CONCAT(O1055,"- ",N1055,"- ",M1055) -> 17- Nov- 1992 | Z1055: 0 | AA1055: 3645.09 | AB1055: tier - 1 | AC1055: tier - 2 | AD1055: R1014 | AE1055: =TEXT(Y1055,"dd/mm/yyyy") -> 17/11/1992 | AF1055: 45085 | AG1055: =DATEDIF(AE1055,AF1055,"y") -> 30
A1056: Id1285 | B1056: 1975 | C1056: Aug | D1056: 6 | E1056: 1 | F1056: 8551.35 | G1056: tier - 2 | H1056: tier - 2 | I1056: R1011 | L1056: Id1947 | M1056: 1985 | N1056: Jun | O1056: 14 | P1056: 3 | Q1056: 3622.13 | R1056: tier - 2 | S1056: tier - 1 | T1056: R1013 | X1056: Id1054 | Y1056: =_xlfn.CONCAT(O1056,"- ",N1056,"- ",M1056) -> 14- Jun- 1985 | Z1056: 3 | AA1056: 3622.13 | AB1056: tier - 2 | AC1056: tier - 1 | AD1056: R1013 | AE1056: =TEXT(Y1056,"dd/mm/yyyy") -> 14/06/1985 | AF1056: 45085 | AG1056: =DATEDIF(AE1056,AF1056,"y") -> 37
A1057: Id1284 | B1057: 1975 | C1057: Aug | D1057: 21 | E1057: 1 | F1057: 8556.91 | G1057: tier - 2 | H1057: tier - 1 | I1057: R1011 | L1057: Id1948 | M1057: 1990 | N1057: Oct | O1057: 11 | P1057: 3 | Q1057: 3606.43 | R1057: tier - 2 | S1057: tier - 1 | T1057: R1013 | X1057: Id1055 | Y1057: =_xlfn.CONCAT(O1057,"- ",N1057,"- ",M1057) -> 11- Oct- 1990 | Z1057: 3 | AA1057: 3606.43 | AB1057: tier - 2 | AC1057: tier - 1 | AD1057: R1013 | AE1057: =TEXT(Y1057,"dd/mm/yyyy") -> 11/10/1990 | AF1057: 45085 | AG1057: =DATEDIF(AE1057,AF1057,"y") -> 32
A1058: Id1283 | B1058: 1988 | C1058: Sep | D1058: 21 | E1058: 3 | F1058: 8567.25 | G1058: tier - 2 | H1058: tier - 1 | I1058: R1012 | L1058: Id1949 | M1058: 1988 | N1058: Nov | O1058: 4 | P1058: 3 | Q1058: 3603.6 | R1058: tier - 2 | S1058: tier - 1 | T1058: R1013 | X1058: Id1056 | Y1058: =_xlfn.CONCAT(O1058,"- ",N1058,"- ",M1058) -> 4- Nov- 1988 | Z1058: 3 | AA1058: 3603.6 | AB1058: tier - 2 | AC1058: tier - 1 | AD1058: R1013 | AE1058: =TEXT(Y1058,"dd/mm/yyyy") -> 04/11/1988 | AF1058: 45085 | AG1058: =DATEDIF(AE1058,AF1058,"y") -> 34
A1059: Id1282 | B1059: 1975 | C1059: Sep | D1059: 26 | E1059: 1 | F1059: 8569.86 | G1059: tier - 2 | H1059: tier - 3 | I1059: R1013 | L1059: Id195 | M1059: 2003 | N1059: Sep | O1059: 5 | P1059: 0 | Q1059: 36219.41 | R1059: tier - 1 | S1059: tier - 1 | T1059: R1012 | X1059: Id1057 | Y1059: =_xlfn.CONCAT(O1059,"- ",N1059,"- ",M1059) -> 5- Sep- 2003 | Z1059: 0 | AA1059: 36219.41 | AB1059: tier - 1 | AC1059: tier - 1 | AD1059: R1012 | AE1059: =TEXT(Y1059,"dd/mm/yyyy") -> 05/09/2003 | AF1059: 45085 | AG1059: =DATEDIF(AE1059,AF1059,"y") -> 19
A1060: Id1281 | B1060: 1982 | C1060: Dec | D1060: 6 | E1060: 3 | F1060: 8572.04 | G1060: tier - 2 | H1060: tier - 2 | I1060: R1021 | L1060: Id1950 | M1060: 1999 | N1060: Aug | O1060: 12 | P1060: 3 | Q1060: 3597.6 | R1060: tier - 2 | S1060: tier - 2 | T1060: R1011 | X1060: Id1058 | Y1060: =_xlfn.CONCAT(O1060,"- ",N1060,"- ",M1060) -> 12- Aug- 1999 | Z1060: 3 | AA1060: 3597.6 | AB1060: tier - 2 | AC1060: tier - 2 | AD1060: R1011 | AE1060: =TEXT(Y1060,"dd/mm/yyyy") -> 12/08/1999 | AF1060: 45085 | AG1060: =DATEDIF(AE1060,AF1060,"y") -> 23
A1061: Id1280 | B1061: 1987 | C1061: Nov | D1061: 11 | E1061: 3 | F1061: 8573.3 | G1061: tier - 2 | H1061: tier - 2 | I1061: R1021 | L1061: Id1951 | M1061: 1997 | N1061: Nov | O1061: 4 | P1061: 1 | Q1061: 3594.17 | R1061: tier - 2 | S1061: tier - 2 | T1061: R1012 | X1061: Id1059 | Y1061: =_xlfn.CONCAT(O1061,"- ",N1061,"- ",M1061) -> 4- Nov- 1997 | Z1061: 1 | AA1061: 3594.17 | AB1061: tier - 2 | AC1061: tier - 2 | AD1061: R1012 | AE1061: =TEXT(Y1061,"dd/mm/yyyy") -> 04/11/1997 | AF1061: 45085 | AG1061: =DATEDIF(AE1061,AF1061,"y") -> 25
A1062: Id1279 | B1062: 1983 | C1062: Dec | D1062: 30 | E1062: 5 | F1062: 8582.3 | G1062: tier - 2 | H1062: tier - 1 | I1062: R1013 | L1062: Id1952 | M1062: 1999 | N1062: Jun | O1062: 6 | P1062: 3 | Q1062: 3591.48 | R1062: tier - 2 | S1062: tier - 3 | T1062: R1011 | X1062: Id1060 | Y1062: =_xlfn.CONCAT(O1062,"- ",N1062,"- ",M1062) -> 6- Jun- 1999 | Z1062: 3 | AA1062: 3591.48 | AB1062: tier - 2 | AC1062: tier - 3 | AD1062: R1011 | AE1062: =TEXT(Y1062,"dd/mm/yyyy") -> 06/06/1999 | AF1062: 45085 | AG1062: =DATEDIF(AE1062,AF1062,"y") -> 24
A1063: Id1278 | B1063: 1983 | C1063: Jul | D1063: 25 | E1063: 5 | F1063: 8596.83 | G1063: tier - 2 | H1063: tier - 3 | I1063: R1013 | L1063: Id1953 | M1063: 1986 | N1063: Dec | O1063: 27 | P1063: 3 | Q1063: 3589.14 | R1063: tier - 2 | S1063: tier - 2 | T1063: R1013 | X1063: Id1061 | Y1063: =_xlfn.CONCAT(O1063,"- ",N1063,"- ",M1063) -> 27- Dec- 1986 | Z1063: 3 | AA1063: 3589.14 | AB1063: tier - 2 | AC1063: tier - 2 | AD1063: R1013 | AE1063: =TEXT(Y1063,"dd/mm/yyyy") -> 27/12/1986 | AF1063: 45085 | AG1063: =DATEDIF(AE1063,AF1063,"y") -> 36
A1064: Id1277 | B1064: 1973 | C1064: Jul | D1064: 11 | E1064: 0 | F1064: 8601.33 | G1064: tier - 2 | H1064: tier - 1 | I1064: R1013 | L1064: Id1954 | M1064: 2001 | N1064: Nov | O1064: 11 | P1064: 2 | Q1064: 3579.83 | R1064: tier - 2 | S1064: tier - 2 | T1064: R1012 | X1064: Id1062 | Y1064: =_xlfn.CONCAT(O1064,"- ",N1064,"- ",M1064) -> 11- Nov- 2001 | Z1064: 2 | AA1064: 3579.83 | AB1064: tier - 2 | AC1064: tier - 2 | AD1064: R1012 | AE1064: =TEXT(Y1064,"dd/mm/yyyy") -> 11/11/2001 | AF1064: 45085 | AG1064: =DATEDIF(AE1064,AF1064,"y") -> 21
A1065: Id1276 | B1065: 1977 | C1065: Sep | D1065: 24 | E1065: 2 | F1065: 8603.82 | G1065: tier - 2 | H1065: tier - 1 | I1065: R1019 | L1065: Id1955 | M1065: 1995 | N1065: Aug | O1065: 23 | P1065: 1 | Q1065: 3578 | R1065: tier - 2 | S1065: tier - 3 | T1065: R1011 | X1065: Id1063 | Y1065: =_xlfn.CONCAT(O1065,"- ",N1065,"- ",M1065) -> 23- Aug- 1995 | Z1065: 1 | AA1065: 3578 | AB1065: tier - 2 | AC1065: tier - 3 | AD1065: R1011 | AE1065: =TEXT(Y1065,"dd/mm/yyyy") -> 23/08/1995 | AF1065: 45085 | AG1065: =DATEDIF(AE1065,AF1065,"y") -> 27
A1066: Id1275 | B1066: 1977 | C1066: Nov | D1066: 12 | E1066: 2 | F1066: 8604.48 | G1066: tier - 3 | H1066: tier - 2 | I1066: R1016 | L1066: Id1956 | M1066: 1988 | N1066: Aug | O1066: 18 | P1066: 3 | Q1066: 3569.96 | R1066: tier - 2 | S1066: tier - 1 | T1066: R1012 | X1066: Id1064 | Y1066: =_xlfn.CONCAT(O1066,"- ",N1066,"- ",M1066) -> 18- Aug- 1988 | Z1066: 3 | AA1066: 3569.96 | AB1066: tier - 2 | AC1066: tier - 1 | AD1066: R1012 | AE1066: =TEXT(Y1066,"dd/mm/yyyy") -> 18/08/1988 | AF1066: 45085 | AG1066: =DATEDIF(AE1066,AF1066,"y") -> 34
A1067: Id1274 | B1067: 1977 | C1067: Oct | D1067: 15 | E1067: 3 | F1067: 8605.36 | G1067: tier - 2 | H1067: tier - 2 | I1067: R1013 | L1067: Id1957 | M1067: 1981 | N1067: Oct | O1067: 10 | P1067: 1 | Q1067: 3562.87 | R1067: tier - 2 | S1067: tier - 1 | T1067: R1013 | X1067: Id1065 | Y1067: =_xlfn.CONCAT(O1067,"- ",N1067,"- ",M1067) -> 10- Oct- 1981 | Z1067: 1 | AA1067: 3562.87 | AB1067: tier - 2 | AC1067: tier - 1 | AD1067: R1013 | AE1067: =TEXT(Y1067,"dd/mm/yyyy") -> 10/10/1981 | AF1067: 45085 | AG1067: =DATEDIF(AE1067,AF1067,"y") -> 41
... A2345: Id1 | B2345: 1968 | C2345: Oct | D2345: 12 | E2345: 0 | F2345: 63770.43 | G2345: tier - 1 | H2345: tier - 3 | I2345: R1013 | L2345: unknown | M2345: 1999 | N2345: Jun | O2345: 9 | P2345: 1 | Q2345: 2775.19 | R2345: tier - 2 | S2345: tier - 1 | T2345: R1012 | X2345: Id2343 | Y2345: =_xlfn.CONCAT(O2345,"- ",N2345,"- ",M2345) -> 9- Jun- 1999 | Z2345: 1 | AA2345: 2775.19 | AB2345: tier - 2 | AC2345: tier - 1 | AD2345: R1012 | AE2345: =TEXT(Y2345,"dd/mm/yyyy") -> 09/06/1999 | AF2345: 45085 | AG2345: =DATEDIF(AE2345,AF2345,"y") -> 23
X2346: Id2344
X2347: Id2345
X2348: Id2346
X2349: Id2347
X2350: Id2348
X2351: Id2349

Sheet healthcare
A1: Customer ID | B1: Customer names | C1: Bmi | D1: HbA1C | E1: Heart issues | F1: Any Transplants | G1: Cancer History | H1: Number of Major surgeries | I1: Smoker | J1: Weight status | K1: Diabetes status | L1: Date of birth | M1: Charges | N1: Hospital_tier | O1: City_tier | P1: State_id | Q1: Age
A2: Id1 | B2: =VLOOKUP(A2,'CUSTOMER NAMES'!E2:H2337,4,FALSE) -> Kelly | C2: =VLOOKUP(A2,'MEDICAL EXAMINATION'!K3:T2337,2,FALSE) -> 47.41 | D2: =VLOOKUP(A2,'MEDICAL EXAMINATION'!K3:T2337,4,FALSE) -> 7.47 | E2: =VLOOKUP(A2,'MEDICAL EXAMINATION'!K3:T2337,6,FALSE) -> No | F2: =VLOOKUP(A2,'MEDICAL EXAMINATION'!K3:T2337,7,FALSE) -> No | G2: =VLOOKUP(A2,'MEDICAL EXAMINATION'!K3:T2337,8,FALSE) -> No | H2: =VLOOKUP(A2,'MEDICAL EXAMINATION'!K3:T2337,9,FALSE) -> No major surgery | I2: =VLOOKUP(A2,'MEDICAL EXAMINATION'!K3:T2337,10,FALSE) -> yes | J2: =VLOOKUP(A2,'MEDICAL EXAMINATION'!K3:T2337,3,FALSE) -> OVERWEIGHT | K2: =VLOOKUP(A2,'MEDICAL EXAMINATION'!K3:T2337,5,FALSE) -> DIABETES | L2: =VLOOKUP(A2,'HOSPITALIZATION DETAILS'!X3:AG2337,8,FALSE) -> 12/10/1968 | M2: =VLOOKUP(A2,'HOSPITALIZATION DETAILS'!X3:AG2337,4,FALSE) -> 63770.43 | N2: =VLOOKUP(A2,'HOSPITALIZATION DETAILS'!X3:AG2337,5,FALSE) -> tier - 1 | O2: =VLOOKUP(A2,'HOSPITALIZATION DETAILS'!X3:AG2337,6,FALSE) -> tier - 3 | P2: =VLOOKUP(A2,'HOSPITALIZATION DETAILS'!X3:AG2337,7,FALSE) -> R1013 | Q2: =VLOOKUP(A2,'HOSPITALIZATION DETAILS'!X3:AG2337,10,FALSE) -> 54
A3: Id2 | B3: =VLOOKUP(A3,'CUSTOMER NAMES'!E3:H2338,4,FALSE) -> Matthew D | C3: =VLOOKUP(A3,'MEDICAL EXAMINATION'!K4:T2338,2,FALSE) -> 30.36 | D3: =VLOOKUP(A3,'MEDICAL EXAMINATION'!K4:T2338,4,FALSE) -> 5.77 | E3: =VLOOKUP(A3,'MEDICAL EXAMINATION'!K4:T2338,6,FALSE) -> No | F3: =VLOOKUP(A3,'MEDICAL EXAMINATION'!K4:T2338,7,FALSE) -> No | G3: =VLOOKUP(A3,'MEDICAL EXAMINATION'!K4:T2338,8,FALSE) -> No | H3: =VLOOKUP(A3,'MEDICAL EXAMINATION'!K4:T2338,9,FALSE) -> No major surgery | I3: =VLOOKUP(A3,'MEDICAL EXAMINATION'!K4:T2338,10,FALSE) -> yes | J3: =VLOOKUP(A3,'MEDICAL EXAMINATION'!K4:T2338,3,FALSE) -> OVERWEIGHT | K3: =VLOOKUP(A3,'MEDICAL EXAMINATION'!K4:T2338,5,FALSE) -> PREDIABETES | L3: =VLOOKUP(A3,'HOSPITALIZATION DETAILS'!X4:AG2338,8,FALSE) -> 29/12/1978 | M3: =VLOOKUP(A3,'HOSPITALIZATION DETAILS'!X4:AG2338,4,FALSE) -> 48885.14 | N3: =VLOOKUP(A3,'HOSPITALIZATION DETAILS'!X4:AG2338,5,FALSE) -> tier - 1 | O3: =VLOOKUP(A3,'HOSPITALIZATION DETAILS'!X4:AG2338,6,FALSE) -> tier - 2 | P3: =VLOOKUP(A3,'HOSPITALIZATION DETAILS'!X4:AG2338,7,FALSE) -> R1013 | Q3: =VLOOKUP(A3,'HOSPITALIZATION DETAILS'!X4:AG2338,10,FALSE) -> 44
A4: Id3 | B4: =VLOOKUP(A4,'CUSTOMER NAMES'!E4:H2339,4,FALSE) -> Phil | C4: =VLOOKUP(A4,'MEDICAL EXAMINATION'!K5:T2339,2,FALSE) -> 34.485 | D4: =VLOOKUP(A4,'MEDICAL EXAMINATION'!K5:T2339,4,FALSE) -> 11.87 | E4: =VLOOKUP(A4,'MEDICAL EXAMINATION'!K5:T2339,6,FALSE) -> yes | F4: =VLOOKUP(A4,'MEDICAL EXAMINATION'!K5:T2339,7,FALSE) -> No | G4: =VLOOKUP(A4,'MEDICAL EXAMINATION'!K5:T2339,8,FALSE) -> No | H4: =VLOOKUP(A4,'MEDICAL EXAMINATION'!K5:T2339,9,FALSE) -> 2 | I4: =VLOOKUP(A4,'MEDICAL EXAMINATION'!K5:T2339,10,FALSE) -> yes | J4: =VLOOKUP(A4,'MEDICAL EXAMINATION'!K5:T2339,3,FALSE) -> OVERWEIGHT | K4: =VLOOKUP(A4,'MEDICAL EXAMINATION'!K5:T2339,5,FALSE) -> DIABETES | L4: =VLOOKUP(A4,'HOSPITALIZATION DETAILS'!X5:AG2339,8,FALSE) -> 27/06/1977 | M4: =VLOOKUP(A4,'HOSPITALIZATION DETAILS'!X5:AG2339,4,FALSE) -> 40284.38 | N4: =VLOOKUP(A4,'HOSPITALIZATION DETAILS'!X5:AG2339,5,FALSE) -> tier - 1 | O4: =VLOOKUP(A4,'HOSPITALIZATION DETAILS'!X5:AG2339,6,FALSE) -> tier - 3 | P4: =VLOOKUP(A4,'HOSPITALIZATION DETAILS'!X5:AG2339,7,FALSE) -> R1012 | Q4: =VLOOKUP(A4,'HOSPITALIZATION DETAILS'!X5:AG2339,10,FALSE) -> 45
A5: Id4 | B5: =VLOOKUP(A5,'CUSTOMER NAMES'!E5:H2340,4,FALSE) -> Kelsey | C5: =VLOOKUP(A5,'MEDICAL EXAMINATION'!K6:T2340,2,FALSE) -> 38.095 | D5: =VLOOKUP(A5,'MEDICAL EXAMINATION'!K6:T2340,4,FALSE) -> 6.05 | E5: =VLOOKUP(A5,'MEDICAL EXAMINATION'!K6:T2340,6,FALSE) -> No | F5: =VLOOKUP(A5,'MEDICAL EXAMINATION'!K6:T2340,7,FALSE) -> No | G5: =VLOOKUP(A5,'MEDICAL EXAMINATION'!K6:T2340,8,FALSE) -> No | H5: =VLOOKUP(A5,'MEDICAL EXAMINATION'!K6:T2340,9,FALSE) -> No major surgery | I5: =VLOOKUP(A5,'MEDICAL EXAMINATION'!K6:T2340,10,FALSE) -> yes | J5: =VLOOKUP(A5,'MEDICAL EXAMINATION'!K6:T2340,3,FALSE) -> OVERWEIGHT | K5: =VLOOKUP(A5,'MEDICAL EXAMINATION'!K6:T2340,5,FALSE) -> PREDIABETES | L5: =VLOOKUP(A5,'HOSPITALIZATION DETAILS'!X6:AG2340,8,FALSE) -> 17/12/1989 | M5: =VLOOKUP(A5,'HOSPITALIZATION DETAILS'!X6:AG2340,4,FALSE) -> 11250.43 | N5: =VLOOKUP(A5,'HOSPITALIZATION DETAILS'!X6:AG2340,5,FALSE) -> tier - 3 | O5: =VLOOKUP(A5,'HOSPITALIZATION DETAILS'!X6:AG2340,6,FALSE) -> tier - 2 | P5: =VLOOKUP(A5,'HOSPITALIZATION DETAILS'!X6:AG2340,7,FALSE) -> R1026 | Q5: =VLOOKUP(A5,'HOSPITALIZATION DETAILS'!X6:AG2340,10,FALSE) -> 33 | T5: AVERAGE
A6: Id5 | B6: =VLOOKUP(A6,'CUSTOMER NAMES'!E6:H2341,4,FALSE) -> Kristyn | C6: =VLOOKUP(A6,'MEDICAL EXAMINATION'!K7:T2341,2,FALSE) -> 35.53 | D6: =VLOOKUP(A6,'MEDICAL EXAMINATION'!K7:T2341,4,FALSE) -> 5.45 | E6: =VLOOKUP(A6,'MEDICAL EXAMINATION'!K7:T2341,6,FALSE) -> No | F6: =VLOOKUP(A6,'MEDICAL EXAMINATION'!K7:T2341,7,FALSE) -> No | G6: =VLOOKUP(A6,'MEDICAL EXAMINATION'!K7:T2341,8,FALSE) -> No | H6: =VLOOKUP(A6,'MEDICAL EXAMINATION'!K7:T2341,9,FALSE) -> No major surgery | I6: =VLOOKUP(A6,'MEDICAL EXAMINATION'!K7:T2341,10,FALSE) -> yes | J6: =VLOOKUP(A6,'MEDICAL EXAMINATION'!K7:T2341,3,FALSE) -> OVERWEIGHT | K6: =VLOOKUP(A6,'MEDICAL EXAMINATION'!K7:T2341,5,FALSE) -> NORMAL | L6: =VLOOKUP(A6,'HOSPITALIZATION DETAILS'!X7:AG2341,8,FALSE) -> 30/12/1969 | M6: =VLOOKUP(A6,'HOSPITALIZATION DETAILS'!X7:AG2341,4,FALSE) -> 11244.38 | N6: =VLOOKUP(A6,'HOSPITALIZATION DETAILS'!X7:AG2341,5,FALSE) -> tier - 3 | O6: =VLOOKUP(A6,'HOSPITALIZATION DETAILS'!X7:AG2341,6,FALSE) -> tier - 1 | P6: =VLOOKUP(A6,'HOSPITALIZATION DETAILS'!X7:AG2341,7,FALSE) -> R1016 | Q6: =VLOOKUP(A6,'HOSPITALIZATION DETAILS'!X7:AG2341,10,FALSE) -> 53 | T6: COLUMNS | U6: VALUES
A7: Id6 | B7: =VLOOKUP(A7,'CUSTOMER NAMES'!E7:H2342,4,FALSE) -> Russell B | C7: =VLOOKUP(A7,'MEDICAL EXAMINATION'!K8:T2342,2,FALSE) -> 32.8 | D7: =VLOOKUP(A7,'MEDICAL EXAMINATION'!K8:T2342,4,FALSE) -> 6.59 | E7: =VLOOKUP(A7,'MEDICAL EXAMINATION'!K8:T2342,6,FALSE) -> No | F7: =VLOOKUP(A7,'MEDICAL EXAMINATION'!K8:T2342,7,FALSE) -> No | G7: =VLOOKUP(A7,'MEDICAL EXAMINATION'!K8:T2342,8,FALSE) -> No | H7: =VLOOKUP(A7,'MEDICAL EXAMINATION'!K8:T2342,9,FALSE) -> No major surgery | I7: =VLOOKUP(A7,'MEDICAL EXAMINATION'!K8:T2342,10,FALSE) -> yes | J7: =VLOOKUP(A7,'MEDICAL EXAMINATION'!K8:T2342,3,FALSE) -> OVERWEIGHT | K7: =VLOOKUP(A7,'MEDICAL EXAMINATION'!K8:T2342,5,FALSE) -> DIABETES | L7: =VLOOKUP(A7,'HOSPITALIZATION DETAILS'!X8:AG2342,8,FALSE) -> 28/06/1976 | M7: =VLOOKUP(A7,'HOSPITALIZATION DETAILS'!X8:AG2342,4,FALSE) -> 11217.35 | N7: =VLOOKUP(A7,'HOSPITALIZATION DETAILS'!X8:AG2342,5,FALSE) -> tier - 3 | O7: =VLOOKUP(A7,'HOSPITALIZATION DETAILS'!X8:AG2342,6,FALSE) -> tier - 2 | P7: =VLOOKUP(A7,'HOSPITALIZATION DETAILS'!X8:AG2342,7,FALSE) -> R1025 | Q7: =VLOOKUP(A7,'HOSPITALIZATION DETAILS'!X8:AG2342,10,FALSE) -> 46 | T7: BMI | U7: =AVERAGE(C:C) -> 30.972649
A8: Id7 | B8: =VLOOKUP(A8,'CUSTOMER NAMES'!E8:H2343,4,FALSE) -> Scott | C8: =VLOOKUP(A8,'MEDICAL EXAMINATION'!K9:T2343,2,FALSE) -> 36.4 | D8: =VLOOKUP(A8,'MEDICAL EXAMINATION'!K9:T2343,4,FALSE) -> 6.07 | E8: =VLOOKUP(A8,'MEDICAL EXAMINATION'!K9:T2343,6,FALSE) -> No | F8: =VLOOKUP(A8,'MEDICAL EXAMINATION'!K9:T2343,7,FALSE) -> No | G8: =VLOOKUP(A8,'MEDICAL EXAMINATION'!K9:T2343,8,FALSE) -> No | H8: =VLOOKUP(A8,'MEDICAL EXAMINATION'!K9:T2343,9,FALSE) -> No major surgery | I8: =VLOOKUP(A8,'MEDICAL EXAMINATION'!K9:T2343,10,FALSE) -> yes | J8: =VLOOKUP(A8,'MEDICAL EXAMINATION'!K9:T2343,3,FALSE) -> OVERWEIGHT | K8: =VLOOKUP(A8,'MEDICAL EXAMINATION'!K9:T2343,5,FALSE) -> PREDIABETES | L8: =VLOOKUP(A8,'HOSPITALIZATION DETAILS'!X9:AG2343,8,FALSE) -> 14/06/1970 | M8: =VLOOKUP(A8,'HOSPITALIZATION DETAILS'!X9:AG2343,4,FALSE) -> 11187.66 | N8: =VLOOKUP(A8,'HOSPITALIZATION DETAILS'!X9:AG2343,5,FALSE) -> tier - 3 | O8: =VLOOKUP(A8,'HOSPITALIZATION DETAILS'!X9:AG2343,6,FALSE) -> tier - 2 | P8: =VLOOKUP(A8,'HOSPITALIZATION DETAILS'!X9:AG2343,7,FALSE) -> R1012 | Q8: =VLOOKUP(A8,'HOSPITALIZATION DETAILS'!X9:AG2343,10,FALSE) -> 52 | T8: CHARGES | U8: =AVERAGE(M:M) -> 13543.956
A9: Id8 | B9: =VLOOKUP(A9,'CUSTOMER NAMES'!E9:H2344,4,FALSE) -> Stephen | C9: =VLOOKUP(A9,'MEDICAL EXAMINATION'!K10:T2344,2,FALSE) -> 36.96 | D9: =VLOOKUP(A9,'MEDICAL EXAMINATION'!K10:T2344,4,FALSE) -> 7.93 | E9: =VLOOKUP(A9,'MEDICAL EXAMINATION'!K10:T2344,6,FALSE) -> No | F9: =VLOOKUP(A9,'MEDICAL EXAMINATION'!K10:T2344,7,FALSE) -> No | G9: =VLOOKUP(A9,'MEDICAL EXAMINATION'!K10:T2344,8,FALSE) -> No | H9: =VLOOKUP(A9,'MEDICAL EXAMINATION'!K10:T2344,9,FALSE) -> 3 | I9: =VLOOKUP(A9,'MEDICAL EXAMINATION'!K10:T2344,10,FALSE) -> yes | J9: =VLOOKUP(A9,'MEDICAL EXAMINATION'!K10:T2344,3,FALSE) -> OVERWEIGHT | K9: =VLOOKUP(A9,'MEDICAL EXAMINATION'!K10:T2344,5,FALSE) -> DIABETES | L9: =VLOOKUP(A9,'HOSPITALIZATION DETAILS'!X10:AG2344,8,FALSE) -> 03/09/1972 | M9: =VLOOKUP(A9,'HOSPITALIZATION DETAILS'!X10:AG2344,4,FALSE) -> 11186.2 | N9: =VLOOKUP(A9,'HOSPITALIZATION DETAILS'!X10:AG2344,5,FALSE) -> tier - 3 | O9: =VLOOKUP(A9,'HOSPITALIZATION DETAILS'!X10:AG2344,6,FALSE) -> tier - 2 | P9: =VLOOKUP(A9,'HOSPITALIZATION DETAILS'!X10:AG2344,7,FALSE) -> R1021 | Q9: =VLOOKUP(A9,'HOSPITALIZATION DETAILS'!X10:AG2344,10,FALSE) -> 50 | T9: HBA1C | U9: =AVERAGE(D:D) -> 6.5789979
A10: Id9 | B10: =VLOOKUP(A10,'CUSTOMER NAMES'!E10:H2345,4,FALSE) -> Patrick R | C10: =VLOOKUP(A10,'MEDICAL EXAMINATION'!K11:T2345,2,FALSE) -> 41.14 | D10: =VLOOKUP(A10,'MEDICAL EXAMINATION'!K11:T2345,4,FALSE) -> 9.58 | E10: =VLOOKUP(A10,'MEDICAL EXAMINATION'!K11:T2345,6,FALSE) -> yes | F10: =VLOOKUP(A10,'MEDICAL EXAMINATION'!K11:T2345,7,FALSE) -> No | G10: =VLOOKUP(A10,'MEDICAL EXAMINATION'!K11:T2345,8,FALSE) -> Yes | H10: =VLOOKUP(A10,'MEDICAL EXAMINATION'!K11:T2345,9,FALSE) -> 1 | I10: =VLOOKUP(A10,'MEDICAL EXAMINATION'!K11:T2345,10,FALSE) -> yes | J10: =VLOOKUP(A10,'MEDICAL EXAMINATION'!K11:T2345,3,FALSE) -> OVERWEIGHT | K10: =VLOOKUP(A10,'MEDICAL EXAMINATION'!K11:T2345,5,FALSE) -> DIABETES | L10: =VLOOKUP(A10,'HOSPITALIZATION DETAILS'!X11:AG2345,8,FALSE) -> 06/08/1966 | M10: =VLOOKUP(A10,'HOSPITALIZATION DETAILS'!X11:AG2345,4,FALSE) -> 11165.42 | N10: =VLOOKUP(A10,'HOSPITALIZATION DETAILS'!X11:AG2345,5,FALSE) -> tier - 3 | O10: =VLOOKUP(A10,'HOSPITALIZATION DETAILS'!X11:AG2345,6,FALSE) -> tier - 1 | P10: =VLOOKUP(A10,'HOSPITALIZATION DETAILS'!X11:AG2345,7,FALSE) -> R1016 | Q10: =VLOOKUP(A10,'HOSPITALIZATION DETAILS'!X11:AG2345,10,FALSE) -> 56
A11: Id10 | B11: =VLOOKUP(A11,'CUSTOMER NAMES'!E11:H2346,4,FALSE) -> Brooke N | C11: =VLOOKUP(A11,'MEDICAL EXAMINATION'!K12:T2346,2,FALSE) -> 38.06 | D11: =VLOOKUP(A11,'MEDICAL EXAMINATION'!K12:T2346,4,FALSE) -> 10.79 | E11: =VLOOKUP(A11,'MEDICAL EXAMINATION'!K12:T2346,6,FALSE) -> No | F11: =VLOOKUP(A11,'MEDICAL EXAMINATION'!K12:T2346,7,FALSE) -> No | G11: =VLOOKUP(A11,'MEDICAL EXAMINATION'!K12:T2346,8,FALSE) -> No | H11: =VLOOKUP(A11,'MEDICAL EXAMINATION'!K12:T2346,9,FALSE) -> No major surgery | I11: =VLOOKUP(A11,'MEDICAL EXAMINATION'!K12:T2346,10,FALSE) -> yes | J11: =VLOOKUP(A11,'MEDICAL EXAMINATION'!K12:T2346,3,FALSE) -> OVERWEIGHT | K11: =VLOOKUP(A11,'MEDICAL EXAMINATION'!K12:T2346,5,FALSE) -> DIABETES | L11: =VLOOKUP(A11,'HOSPITALIZATION DETAILS'!X12:AG2346,8,FALSE) -> 25/06/1969 | M11: =VLOOKUP(A11,'HOSPITALIZATION DETAILS'!X12:AG2346,4,FALSE) -> 11163.57 | N11: =VLOOKUP(A11,'HOSPITALIZATION DETAILS'!X12:AG2346,5,FALSE) -> tier - 3 | O11: =VLOOKUP(A11,'HOSPITALIZATION DETAILS'!X12:AG2346,6,FALSE) -> tier - 2 | P11: =VLOOKUP(A11,'HOSPITALIZATION DETAILS'!X12:AG2346,7,FALSE) -> R1011 | Q11: =VLOOKUP(A11,'HOSPITALIZATION DETAILS'!X12:AG2346,10,FALSE) -> 53 | T11: SUM
A12: Id11 | B12: =VLOOKUP(A12,'CUSTOMER NAMES'!E12:H2347,4,FALSE) -> Paola Andrea | C12: =VLOOKUP(A12,'MEDICAL EXAMINATION'!K13:T2347,2,FALSE) -> 37.7 | D12: =VLOOKUP(A12,'MEDICAL EXAMINATION'!K13:T2347,4,FALSE) -> 5.96 | E12: =VLOOKUP(A12,'MEDICAL EXAMINATION'!K13:T2347,6,FALSE) -> yes | F12: =VLOOKUP(A12,'MEDICAL EXAMINATION'!K13:T2347,7,FALSE) -> No | G12: =VLOOKUP(A12,'MEDICAL EXAMINATION'!K13:T2347,8,FALSE) -> No | H12: =VLOOKUP(A12,'MEDICAL EXAMINATION'!K13:T2347,9,FALSE) -> 2 | I12: =VLOOKUP(A12,'MEDICAL EXAMINATION'!K13:T2347,10,FALSE) -> yes | J12: =VLOOKUP(A12,'MEDICAL EXAMINATION'!K13:T2347,3,FALSE) -> OVERWEIGHT | K12: =VLOOKUP(A12,'MEDICAL EXAMINATION'!K13:T2347,5,FALSE) -> PREDIABETES | L12: =VLOOKUP(A12,'HOSPITALIZATION DETAILS'!X13:AG2347,8,FALSE) -> 30/11/1969 | M12: =VLOOKUP(A12,'HOSPITALIZATION DETAILS'!X13:AG2347,4,FALSE) -> 11150.78 | N12: =VLOOKUP(A12,'HOSPITALIZATION DETAILS'!X13:AG2347,5,FALSE) -> tier - 3 | O12: =VLOOKUP(A12,'HOSPITALIZATION DETAILS'!X13:AG2347,6,FALSE) -> tier - 2 | P12: =VLOOKUP(A12,'HOSPITALIZATION DETAILS'!X13:AG2347,7,FALSE) -> R1011 | Q12: =VLOOKUP(A12,'HOSPITALIZATION DETAILS'!X13:AG2347,10,FALSE) -> 53 | T12: MAJOR SURGERIES | U12: =SUM(H:H) -> 1579
A13: Id12 | B13: =VLOOKUP(A13,'CUSTOMER NAMES'!E13:H2348,4,FALSE) -> David | C13: =VLOOKUP(A13,'MEDICAL EXAMINATION'!K14:T2348,2,FALSE) -> 42.13 | D13: =VLOOKUP(A13,'MEDICAL EXAMINATION'!K14:T2348,4,FALSE) -> 11.9 | E13: =VLOOKUP(A13,'MEDICAL EXAMINATION'!K14:T2348,6,FALSE) -> No | F13: =VLOOKUP(A13,'MEDICAL EXAMINATION'!K14:T2348,7,FALSE) -> No | G13: =VLOOKUP(A13,'MEDICAL EXAMINATION'!K14:T2348,8,FALSE) -> No | H13: =VLOOKUP(A13,'MEDICAL EXAMINATION'!K14:T2348,9,FALSE) -> No major surgery | I13: =VLOOKUP(A13,'MEDICAL EXAMINATION'!K14:T2348,10,FALSE) -> yes | J13: =VLOOKUP(A13,'MEDICAL EXAMINATION'!K14:T2348,3,FALSE) -> OVERWEIGHT | K13: =VLOOKUP(A13,'MEDICAL EXAMINATION'!K14:T2348,5,FALSE) -> DIABETES | L13: =VLOOKUP(A13,'HOSPITALIZATION DETAILS'!X14:AG2348,8,FALSE) -> 20/08/1980 | M13: =VLOOKUP(A13,'HOSPITALIZATION DETAILS'!X14:AG2348,4,FALSE) -> 11103.33 | N13: =VLOOKUP(A13,'HOSPITALIZATION DETAILS'!X14:AG2348,5,FALSE) -> tier - 3 | O13: =VLOOKUP(A13,'HOSPITALIZATION DETAILS'!X14:AG2348,6,FALSE) -> tier - 1 | P13: =VLOOKUP(A13,'HOSPITALIZATION DETAILS'!X14:AG2348,7,FALSE) -> R1021 | Q13: =VLOOKUP(A13,'HOSPITALIZATION DETAILS'!X14:AG2348,10,FALSE) -> 42
A14: Id13 | B14: =VLOOKUP(A14,'CUSTOMER NAMES'!E14:H2349,4,FALSE) -> Wade | C14: =VLOOKUP(A14,'MEDICAL EXAMINATION'!K15:T2349,2,FALSE) -> 40.92 | D14: =VLOOKUP(A14,'MEDICAL EXAMINATION'!K15:T2349,4,FALSE) -> 8.41 | E14: =VLOOKUP(A14,'MEDICAL EXAMINATION'!K15:T2349,6,FALSE) -> No | F14: =VLOOKUP(A14,'MEDICAL EXAMINATION'!K15:T2349,7,FALSE) -> No | G14: =VLOOKUP(A14,'MEDICAL EXAMINATION'!K15:T2349,8,FALSE) -> No | H14: =VLOOKUP(A14,'MEDICAL EXAMINATION'!K15:T2349,9,FALSE) -> No major surgery | I14: =VLOOKUP(A14,'MEDICAL EXAMINATION'!K15:T2349,10,FALSE) -> yes | J14: =VLOOKUP(A14,'MEDICAL EXAMINATION'!K15:T2349,3,FALSE) -> OVERWEIGHT | K14: =VLOOKUP(A14,'MEDICAL EXAMINATION'!K15:T2349,5,FALSE) -> DIABETES | L14: =VLOOKUP(A14,'HOSPITALIZATION DETAILS'!X15:AG2349,8,FALSE) -> 05/07/1966 | M14: =VLOOKUP(A14,'HOSPITALIZATION DETAILS'!X15:AG2349,4,FALSE) -> 11093.62 | N14: =VLOOKUP(A14,'HOSPITALIZATION DETAILS'!X15:AG2349,5,FALSE) -> tier - 3 | O14: =VLOOKUP(A14,'HOSPITALIZATION DETAILS'!X15:AG2349,6,FALSE) -> tier - 1 | P14: =VLOOKUP(A14,'HOSPITALIZATION DETAILS'!X15:AG2349,7,FALSE) -> R1013 | Q14: =VLOOKUP(A14,'HOSPITALIZATION DETAILS'!X15:AG2349,10,FALSE) -> 56
A15: Id14 | B15: =VLOOKUP(A15,'CUSTOMER NAMES'!E15:H2350,4,FALSE) -> Franklin | C15: =VLOOKUP(A15,'MEDICAL EXAMINATION'!K16:T2350,2,FALSE) -> 40.565 | D15: =VLOOKUP(A15,'MEDICAL EXAMINATION'!K16:T2350,4,FALSE) -> 7.02 | E15: =VLOOKUP(A15,'MEDICAL EXAMINATION'!K16:T2350,6,FALSE) -> No | F15: =VLOOKUP(A15,'MEDICAL EXAMINATION'!K16:T2350,7,FALSE) -> No | G15: =VLOOKUP(A15,'MEDICAL EXAMINATION'!K16:T2350,8,FALSE) -> No | H15: =VLOOKUP(A15,'MEDICAL EXAMINATION'!K16:T2350,9,FALSE) -> No major surgery | I15: =VLOOKUP(A15,'MEDICAL EXAMINATION'!K16:T2350,10,FALSE) -> yes | J15: =VLOOKUP(A15,'MEDICAL EXAMINATION'!K16:T2350,3,FALSE) -> OVERWEIGHT | K15: =VLOOKUP(A15,'MEDICAL EXAMINATION'!K16:T2350,5,FALSE) -> DIABETES | L15: =VLOOKUP(A15,'HOSPITALIZATION DETAILS'!X16:AG2350,8,FALSE) -> 04/10/1981 | M15: =VLOOKUP(A15,'HOSPITALIZATION DETAILS'!X16:AG2350,4,FALSE) -> 40273.65 | N15: =VLOOKUP(A15,'HOSPITALIZATION DETAILS'!X16:AG2350,5,FALSE) -> tier - 1 | O15: =VLOOKUP(A15,'HOSPITALIZATION DETAILS'!X16:AG2350,6,FALSE) -> tier - 3 | P15: =VLOOKUP(A15,'HOSPITALIZATION DETAILS'!X16:AG2350,7,FALSE) -> R1013 | Q15: =VLOOKUP(A15,'HOSPITALIZATION DETAILS'!X16:AG2350,10,FALSE) -> 41
A16: Id15 | B16: =VLOOKUP(A16,'CUSTOMER NAMES'!E16:H2351,4,FALSE) -> Leilani M | C16: =VLOOKUP(A16,'MEDICAL EXAMINATION'!K17:T2351,2,FALSE) -> 36.385 | D16: =VLOOKUP(A16,'MEDICAL EXAMINATION'!K17:T2351,4,FALSE) -> 7.59 | E16: =VLOOKUP(A16,'MEDICAL EXAMINATION'!K17:T2351,6,FALSE) -> yes | F16: =VLOOKUP(A16,'MEDICAL EXAMINATION'!K17:T2351,7,FALSE) -> No | G16: =VLOOKUP(A16,'MEDICAL EXAMINATION'!K17:T2351,8,FALSE) -> No | H16: =VLOOKUP(A16,'MEDICAL EXAMINATION'!K17:T2351,9,FALSE) -> 2 | I16: =VLOOKUP(A16,'MEDICAL EXAMINATION'!K17:T2351,10,FALSE) -> yes | J16: =VLOOKUP(A16,'MEDICAL EXAMINATION'!K17:T2351,3,FALSE) -> OVERWEIGHT | K16: =VLOOKUP(A16,'MEDICAL EXAMINATION'!K17:T2351,5,FALSE) -> DIABETES | L16: =VLOOKUP(A16,'HOSPITALIZATION DETAILS'!X17:AG2351,8,FALSE) -> 09/09/1966 | M16: =VLOOKUP(A16,'HOSPITALIZATION DETAILS'!X17:AG2351,4,FALSE) -> 11090.72 | N16: =VLOOKUP(A16,'HOSPITALIZATION DETAILS'!X17:AG2351,5,FALSE) -> tier - 3 | O16: =VLOOKUP(A16,'HOSPITALIZATION DETAILS'!X17:AG2351,6,FALSE) -> tier - 1 | P16: =VLOOKUP(A16,'HOSPITALIZATION DETAILS'!X17:AG2351,7,FALSE) -> R1013 | Q16: =VLOOKUP(A16,'HOSPITALIZATION DETAILS'!X17:AG2351,10,FALSE) -> 56
A17: Id16 | B17: =VLOOKUP(A17,'CUSTOMER NAMES'!E17:H2352,4,FALSE) -> Philippe | C17: =VLOOKUP(A17,'MEDICAL EXAMINATION'!K18:T2352,2,FALSE) -> 39.9 | D17: =VLOOKUP(A17,'MEDICAL EXAMINATION'!K18:T2352,4,FALSE) -> 11.32 | E17: =VLOOKUP(A17,'MEDICAL EXAMINATION'!K18:T2352,6,FALSE) -> No | F17: =VLOOKUP(A17,'MEDICAL EXAMINATION'!K18:T2352,7,FALSE) -> No | G17: =VLOOKUP(A17,'MEDICAL EXAMINATION'!K18:T2352,8,FALSE) -> No | H17: =VLOOKUP(A17,'MEDICAL EXAMINATION'!K18:T2352,9,FALSE) -> No major surgery | I17: =VLOOKUP(A17,'MEDICAL EXAMINATION'!K18:T2352,10,FALSE) -> yes | J17: =VLOOKUP(A17,'MEDICAL EXAMINATION'!K18:T2352,3,FALSE) -> OVERWEIGHT | K17: =VLOOKUP(A17,'MEDICAL EXAMINATION'!K18:T2352,5,FALSE) -> DIABETES | L17: =VLOOKUP(A17,'HOSPITALIZATION DETAILS'!X18:AG2352,8,FALSE) -> 07/10/1972 | M17: =VLOOKUP(A17,'HOSPITALIZATION DETAILS'!X18:AG2352,4,FALSE) -> 11085.59 | N17: =VLOOKUP(A17,'HOSPITALIZATION DETAILS'!X18:AG2352,5,FALSE) -> tier - 3 | O17: =VLOOKUP(A17,'HOSPITALIZATION DETAILS'!X18:AG2352,6,FALSE) -> tier - 2 | P17: =VLOOKUP(A17,'HOSPITALIZATION DETAILS'!X18:AG2352,7,FALSE) -> R1012 | Q17: =VLOOKUP(A17,'HOSPITALIZATION DETAILS'!X18:AG2352,10,FALSE) -> 50
A18: Id17 | B18: =VLOOKUP(A18,'CUSTOMER NAMES'!E18:H2353,4,FALSE) -> Jennifer A | C18: =VLOOKUP(A18,'MEDICAL EXAMINATION'!K19:T2353,2,FALSE) -> 33.8 | D18: =VLOOKUP(A18,'MEDICAL EXAMINATION'!K19:T2353,4,FALSE) -> 7.67 | E18: =VLOOKUP(A18,'MEDICAL EXAMINATION'!K19:T2353,6,FALSE) -> No | F18: =VLOOKUP(A18,'MEDICAL EXAMINATION'!K19:T2353,7,FALSE) -> No | G18: =VLOOKUP(A18,'MEDICAL EXAMINATION'!K19:T2353,8,FALSE) -> No | H18: =VLOOKUP(A18,'MEDICAL EXAMINATION'!K19:T2353,9,FALSE) -> 3 | I18: =VLOOKUP(A18,'MEDICAL EXAMINATION'!K19:T2353,10,FALSE) -> yes | J18: =VLOOKUP(A18,'MEDICAL EXAMINATION'!K19:T2353,3,FALSE) -> OVERWEIGHT | K18: =VLOOKUP(A18,'MEDICAL EXAMINATION'!K19:T2353,5,FALSE) -> DIABETES | L18: =VLOOKUP(A18,'HOSPITALIZATION DETAILS'!X19:AG2353,8,FALSE) -> 04/09/1967 | M18: =VLOOKUP(A18,'HOSPITALIZATION DETAILS'!X19:AG2353,4,FALSE) -> 11082.58 | N18: =VLOOKUP(A18,'HOSPITALIZATION DETAILS'!X19:AG2353,5,FALSE) -> tier - 3 | O18: =VLOOKUP(A18,'HOSPITALIZATION DETAILS'!X19:AG2353,6,FALSE) -> tier - 2 | P18: =VLOOKUP(A18,'HOSPITALIZATION DETAILS'!X19:AG2353,7,FALSE) -> R1012 | Q18: =VLOOKUP(A18,'HOSPITALIZATION DETAILS'!X19:AG2353,10,FALSE) -> 55
A19: Id18 | B19: =VLOOKUP(A19,'CUSTOMER NAMES'!E19:H2354,4,FALSE) -> Christina M | C19: =VLOOKUP(A19,'MEDICAL EXAMINATION'!K20:T2354,2,FALSE) -> 36.765 | D19: =VLOOKUP(A19,'MEDICAL EXAMINATION'!K20:T2354,4,FALSE) -> 7.29 | E19: =VLOOKUP(A19,'MEDICAL EXAMINATION'!K20:T2354,6,FALSE) -> yes | F19: =VLOOKUP(A19,'MEDICAL EXAMINATION'!K20:T2354,7,FALSE) -> No | G19: =VLOOKUP(A19,'MEDICAL EXAMINATION'!K20:T2354,8,FALSE) -> Yes | H19: =VLOOKUP(A19,'MEDICAL EXAMINATION'!K20:T2354,9,FALSE) -> 1 | I19: =VLOOKUP(A19,'MEDICAL EXAMINATION'!K20:T2354,10,FALSE) -> yes | J19: =VLOOKUP(A19,'MEDICAL EXAMINATION'!K20:T2354,3,FALSE) -> OVERWEIGHT | K19: =VLOOKUP(A19,'MEDICAL EXAMINATION'!K20:T2354,5,FALSE) -> DIABETES | L19: =VLOOKUP(A19,'HOSPITALIZATION DETAILS'!X20:AG2354,8,FALSE) -> 20/11/1966 | M19: =VLOOKUP(A19,'HOSPITALIZATION DETAILS'!X20:AG2354,4,FALSE) -> 11073.18 | N19: =VLOOKUP(A19,'HOSPITALIZATION DETAILS'!X20:AG2354,5,FALSE) -> tier - 3 | O19: =VLOOKUP(A19,'HOSPITALIZATION DETAILS'!X20:AG2354,6,FALSE) -> tier - 3 | P19: =VLOOKUP(A19,'HOSPITALIZATION DETAILS'!X20:AG2354,7,FALSE) -> R1011 | Q19: =VLOOKUP(A19,'HOSPITALIZATION DETAILS'!X20:AG2354,10,FALSE) -> 56
A20: Id19 | B20: =VLOOKUP(A20,'CUSTOMER NAMES'!E20:H2355,4,FALSE) -> Said Sr | C20: =VLOOKUP(A20,'MEDICAL EXAMINATION'!K21:T2355,2,FALSE) -> 36.955 | D20: =VLOOKUP(A20,'MEDICAL EXAMINATION'!K21:T2355,4,FALSE) -> 4.72 | E20: =VLOOKUP(A20,'MEDICAL EXAMINATION'!K21:T2355,6,FALSE) -> yes | F20: =VLOOKUP(A20,'MEDICAL EXAMINATION'!K21:T2355,7,FALSE) -> No | G20: =VLOOKUP(A20,'MEDICAL EXAMINATION'!K21:T2355,8,FALSE) -> No | H20: =VLOOKUP(A20,'MEDICAL EXAMINATION'!K21:T2355,9,FALSE) -> 1 | I20: =VLOOKUP(A20,'MEDICAL EXAMINATION'!K21:T2355,10,FALSE) -> yes | J20: =VLOOKUP(A20,'MEDICAL EXAMINATION'!K21:T2355,3,FALSE) -> OVERWEIGHT | K20: =VLOOKUP(A20,'MEDICAL EXAMINATION'!K21:T2355,5,FALSE) -> NORMAL | L20: =VLOOKUP(A20,'HOSPITALIZATION DETAILS'!X21:AG2355,8,FALSE) -> 07/11/1966 | M20: =VLOOKUP(A20,'HOSPITALIZATION DETAILS'!X21:AG2355,4,FALSE) -> 11070.54 | N20: =VLOOKUP(A20,'HOSPITALIZATION DETAILS'!X21:AG2355,5,FALSE) -> tier - 3 | O20: =VLOOKUP(A20,'HOSPITALIZATION DETAILS'!X21:AG2355,6,FALSE) -> tier - 3 | P20: =VLOOKUP(A20,'HOSPITALIZATION DETAILS'!X21:AG2355,7,FALSE) -> R1011 | Q20: =VLOOKUP(A20,'HOSPITALIZATION DETAILS'!X21:AG2355,10,FALSE) -> 56
A21: Id20 | B21: =VLOOKUP(A21,'CUSTOMER NAMES'!E21:H2356,4,FALSE) -> John | C21: =VLOOKUP(A21,'MEDICAL EXAMINATION'!K22:T2356,2,FALSE) -> 42.9 | D21: =VLOOKUP(A21,'MEDICAL EXAMINATION'!K22:T2356,4,FALSE) -> 11.41 | E21: =VLOOKUP(A21,'MEDICAL EXAMINATION'!K22:T2356,6,FALSE) -> No | F21: =VLOOKUP(A21,'MEDICAL EXAMINATION'!K22:T2356,7,FALSE) -> No | G21: =VLOOKUP(A21,'MEDICAL EXAMINATION'!K22:T2356,8,FALSE) -> No | H21: =VLOOKUP(A21,'MEDICAL EXAMINATION'!K22:T2356,9,FALSE) -> No major surgery | I21: =VLOOKUP(A21,'MEDICAL EXAMINATION'!K22:T2356,10,FALSE) -> yes | J21: =VLOOKUP(A21,'MEDICAL EXAMINATION'!K22:T2356,3,FALSE) -> OVERWEIGHT | K21: =VLOOKUP(A21,'MEDICAL EXAMINATION'!K22:T2356,5,FALSE) -> DIABETES | L21: =VLOOKUP(A21,'HOSPITALIZATION DETAILS'!X22:AG2356,8,FALSE) -> 09/11/1971 | M21: =VLOOKUP(A21,'HOSPITALIZATION DETAILS'!X22:AG2356,4,FALSE) -> 11068.77 | N21: =VLOOKUP(A21,'HOSPITALIZATION DETAILS'!X22:AG2356,5,FALSE) -> tier - 3 | O21: =VLOOKUP(A21,'HOSPITALIZATION DETAILS'!X22:AG2356,6,FALSE) -> tier - 2 | P21: =VLOOKUP(A21,'HOSPITALIZATION DETAILS'!X22:AG2356,7,FALSE) -> R1012 | Q21: =VLOOKUP(A21,'HOSPITALIZATION DETAILS'!X22:AG2356,10,FALSE) -> 51
A22: Id21 | B22: =VLOOKUP(A22,'CUSTOMER NAMES'!E22:H2357,4,FALSE) -> Myles | C22: =VLOOKUP(A22,'MEDICAL EXAMINATION'!K23:T2357,2,FALSE) -> 36.3 | D22: =VLOOKUP(A22,'MEDICAL EXAMINATION'!K23:T2357,4,FALSE) -> 11.5 | E22: =VLOOKUP(A22,'MEDICAL EXAMINATION'!K23:T2357,6,FALSE) -> yes | F22: =VLOOKUP(A22,'MEDICAL EXAMINATION'!K23:T2357,7,FALSE) -> No | G22: =VLOOKUP(A22,'MEDICAL EXAMINATION'!K23:T2357,8,FALSE) -> No | H22: =VLOOKUP(A22,'MEDICAL EXAMINATION'!K23:T2357,9,FALSE) -> 2 | I22: =VLOOKUP(A22,'MEDICAL EXAMINATION'!K23:T2357,10,FALSE) -> yes | J22: =VLOOKUP(A22,'MEDICAL EXAMINATION'!K23:T2357,3,FALSE) -> OVERWEIGHT | K22: =VLOOKUP(A22,'MEDICAL EXAMINATION'!K23:T2357,5,FALSE) -> DIABETES | L22: =VLOOKUP(A22,'HOSPITALIZATION DETAILS'!X23:AG2357,8,FALSE) -> 18/09/2000 | M22: =VLOOKUP(A22,'HOSPITALIZATION DETAILS'!X23:AG2357,4,FALSE) -> 11068.7 | N22: =VLOOKUP(A22,'HOSPITALIZATION DETAILS'!X23:AG2357,5,FALSE) -> tier - 3 | O22: =VLOOKUP(A22,'HOSPITALIZATION DETAILS'!X23:AG2357,6,FALSE) -> tier - 1 | P22: =VLOOKUP(A22,'HOSPITALIZATION DETAILS'!X23:AG2357,7,FALSE) -> R1011 | Q22: =VLOOKUP(A22,'HOSPITALIZATION DETAILS'!X23:AG2357,10,FALSE) -> 22
